Workbook

Sheet Synthese
A1: Entreprise de construction – base Orléans – croissance non maîtrisée
A3: Date d'analyse | B3: 46104
A4: Périmètre de génération | B4: 01/01/2023 au 31/12/2025
A5: Volumétrie | B5: 80 chantiers | 272 factures | 694 lignes de coûts
A6: Scénario | B6: CA en hausse, marge EBE en dégradation, coûts cachés plus visibles en 2025
A8: Cascade EBE par année
A9: Indicateur | B9: 2023 | C9: 2024 | D9: 2025
A10: CA chantiers HT | B10: =SUMIFS(Chantiers!$L:$L,Chantiers!$M:$M,2023) -> 2153400 | C10: =SUMIFS(Chantiers!$L:$L,Chantiers!$M:$M,2024) -> 4091600 | D10: =SUMIFS(Chantiers!$L:$L,Chantiers!$M:$M,2025) -> 6313500
A11: Achats consommés | B11: =SUMIFS(Couts!$E:$E,Couts!$D:$D,"Achats",Couts!$F:$F,2023) -> 948156 | C11: =SUMIFS(Couts!$E:$E,Couts!$D:$D,"Achats",Couts!$F:$F,2024) -> 1816236 | D11: =SUMIFS(Couts!$E:$E,Couts!$D:$D,"Achats",Couts!$F:$F,2025) -> 2910028
A12: Charges externes | B12: =SUMIFS(Couts!$E:$E,Couts!$D:$D,"Charges externes",Couts!$F:$F,2023) -> 277085 | C12: =SUMIFS(Couts!$E:$E,Couts!$D:$D,"Charges externes",Couts!$F:$F,2024) -> 703271 | D12: =SUMIFS(Couts!$E:$E,Couts!$D:$D,"Charges externes",Couts!$F:$F,2025) -> 1360828
A13: Charges de personnel | B13: =SUMIFS(Couts!$E:$E,Couts!$D:$D,"Personnel",Couts!$F:$F,2023) -> 539938 | C13: =SUMIFS(Couts!$E:$E,Couts!$D:$D,"Personnel",Couts!$F:$F,2024) -> 1154793 | D13: =SUMIFS(Couts!$E:$E,Couts!$D:$D,"Personnel",Couts!$F:$F,2025) -> 1887356
A14: EBE | B14: =B10-SUM(B11:B13) -> 388221 | C14: =C10-SUM(C11:C13) -> 417300 | D14: =D10-SUM(D11:D13) -> 155288
A15: Marge EBE % | B15: =IFERROR(B14/B10,0) -> 0.18028281 | C15: =IFERROR(C14/C10,0) -> 0.10198944 | D15: =IFERROR(D14/D10,0) -> 0.024596183
A18: Cash & recouvrement
A19: Indicateur | B19: Valeur | C19: Lecture
A20: Montant encaissé au 23/03/2026 | B20: =SUMIFS(Factures!$E:$E,Factures!$F:$F,"<="&$B$3) -> 12006975 | C20: Cash réellement entré
A21: Encours client au 23/03/2026 | B21: =SUM(Factures!$I$2:$I$273) -> 551525 | C21: Facturé non encaissé
A22: Factures en retard | B22: =SUM(Factures!$H$2:$H$273) -> 14 | C22: Base de relance
A23: Montant en retard | B23: =SUM(Factures!$J$2:$J$273) -> 551525 | C23: Impayés exigibles
A26: Points à raconter dans le case study
A27: • La croissance du CA est portée par davantage de chantiers et des chantiers plus gros en 2025.
A28: • Les charges externes et les coûts de personnel progressent plus vite que le CA.
A29: • Les collectivités et promoteurs montrent des délais de paiement plus longs.
A30: • Les coûts sont ventilés dans des lignes séparées : les fichiers Excel distincts masquent la dérive globale.

Sheet Chantiers
A1: chantier_id | B1: nom_chantier | C1: client | D1: type_client | E1: type_travaux | F1: code_postal | G1: ville | H1: date_debut | I1: date_fin_prevue | J1: date_fin_reelle | K1: ca_prevu_ht | L1: ca_facture_ht | M1: annee_debut
A2: CH-2023-001 | B2: Dallage aire PL - La Chapelle-Saint-Mesmin | C2: Commune des Trois Ponts | D2: Collectivité | E2: Pavage / dallage | F2: 45380 | G2: La Chapelle-Saint-Mesmin | H2: 45128 | I2: 45151 | J2: 45148 | K2: 44600 | L2: 43700 | M2: 2023
A3: CH-2023-002 | B3: Dépôt structure - Orléans | C3: Feronex Centre | D3: Entreprise | E3: Gros œuvre | F3: 45000 | G3: Orléans | H3: 45218 | I3: 45342 | J3: 45340 | K3: 147300 | L3: 145300 | M3: 2023
A4: CH-2023-003 | B4: Résidence chantier - Orléans | C4: Promovia Terrains | D4: Promoteur | E4: Ravalement | F4: 45000 | G4: Orléans | H4: 45267 | I4: 45337 | J4: 45351 | K4: 64400 | L4: 65100 | M4: 2023
A5: CH-2023-004 | B5: Extension structure - Fleury-les-Aubrais | C5: Habitat Loire | D5: Bailleur social | E5: Gros œuvre | F5: 45400 | G5: Fleury-les-Aubrais | H5: 45027 | I5: 45132 | J5: 45133 | K5: 116800 | L5: 114100 | M5: 2023
A6: CH-2023-005 | B6: Annexe chantier - Saint-Jean-de-la-Ruelle | C6: Coriance Val de Loire | D6: Entreprise | E6: Maçonnerie | F6: 45140 | G6: Saint-Jean-de-la-Ruelle | H6: 45066 | I6: 45102 | J6: 45100 | K6: 33200 | L6: 34500 | M6: 2023
A7: CH-2023-006 | B7: Plateforme structure - Saran | C7: Carrévia Développement | D7: Promoteur | E7: Gros œuvre | F7: 45770 | G7: Saran | H7: 45073 | I7: 45189 | J7: 45204 | K7: 102000 | L7: 103700 | M7: 2023
A8: CH-2023-007 | B8: Démolition chantier - Fleury-les-Aubrais | C8: Ville Loire Sud | D8: Collectivité | E8: Démolition / curage | F8: 45400 | G8: Fleury-les-Aubrais | H8: 45105 | I8: 45131 | J8: 45140 | K8: 128300 | L8: 131900 | M8: 2023
A9: CH-2023-008 | B9: Dépôt structure - Olivet | C9: Domiref Promotion | D9: Promoteur | E9: Gros œuvre | F9: 45160 | G9: Olivet | H9: 45023 | I9: 45127 | J9: 45126 | K9: 154200 | L9: 151300 | M9: 2023
A10: CH-2023-009 | B10: Esplanade aire PL - Le Coudray | C10: Nexora Concept | D10: Entreprise | E10: Pavage / dallage | F10: 28630 | G10: Le Coudray | H10: 45207 | I10: 45248 | J10: 45255 | K10: 83900 | L10: 81600 | M10: 2023
A11: CH-2023-010 | B11: Extension structure - Chécy | C11: Mécadia Services | D11: Entreprise | E11: Gros œuvre | F11: 45430 | G11: Chécy | H11: 45080 | I11: 45177 | J11: 45192 | K11: 220900 | L11: 220400 | M11: 2023
A12: CH-2023-011 | B12: Unité logistique - Orléans | C12: Coriance Logistique | D12: Entreprise | E12: Bâtiment industriel | F12: 45000 | G12: Orléans | H12: 45235 | I12: 45366 | J12: 45389 | K12: 252300 | L12: 260600 | M12: 2023
A13: CH-2023-012 | B13: Façades chantier - Saran | C13: Atriumis Concept | D13: Entreprise | E13: Ravalement | F13: 45770 | G13: Saran | H13: 45112 | I13: 45169 | J13: 45181 | K13: 91400 | L13: 89400 | M13: 2023
... A81: CH-2025-036 | B81: Plateforme structure - Orléans Sud | C81: Pôle public des Rives | D81: Collectivité | E81: Gros œuvre | F81: 45100 | G81: Orléans Sud | H81: 45777 | I81: 45903 | J81: 45927 | K81: 291700 | L81: 308000 | M81: 2025

Sheet Couts
A1: cout_id | B1: chantier_id | C1: date | D1: type_cout | E1: montant_ht | F1: annee_chantier
A2: COUT-0001 | B2: CH-2023-001 | C2: 45138 | D2: Achats | E2: 14165 | F2: 2023
A3: COUT-0002 | B3: CH-2023-001 | C3: 45132 | D3: Achats | E3: 5237 | F3: 2023
A4: COUT-0003 | B4: CH-2023-001 | C4: 45164 | D4: Charges externes | E4: 2028 | F4: 2023
A5: COUT-0004 | B5: CH-2023-001 | C5: 45151 | D5: Charges externes | E5: 793 | F5: 2023
A6: COUT-0005 | B6: CH-2023-001 | C6: 45153 | D6: Charges externes | E6: 2593 | F6: 2023
A7: COUT-0006 | B7: CH-2023-001 | C7: 45138 | D7: Personnel | E7: 2651 | F7: 2023
A8: COUT-0007 | B8: CH-2023-001 | C8: 45139 | D8: Personnel | E8: 2871 | F8: 2023
A9: COUT-0008 | B9: CH-2023-001 | C9: 45140 | D9: Personnel | E9: 5308 | F9: 2023
A10: COUT-0009 | B10: CH-2023-002 | C10: 45244 | D10: Achats | E10: 33519 | F10: 2023
A11: COUT-0010 | B11: CH-2023-002 | C11: 45221 | D11: Achats | E11: 21217 | F11: 2023
A12: COUT-0011 | B12: CH-2023-002 | C12: 45225 | D12: Achats | E12: 9091 | F12: 2023
A13: COUT-0012 | B13: CH-2023-002 | C13: 45296 | D13: Charges externes | E13: 17812 | F13: 2023
... A695: COUT-0694 | B695: CH-2025-036 | C695: 45888 | D695: Personnel | E695: 13434 | F695: 2025

Sheet Factures
A1: facture_id | B1: chantier_id | C1: date_facture | D1: date_echeance | E1: montant_ht | F1: date_paiement | G1: est_impayee_23032026 | H1: est_retard_23032026 | I1: montant_encours_23032026 | J1: montant_retard_23032026
A2: FAC-0001 | B2: CH-2023-001 | C2: 45135 | D2: 45180 | E2: 17480 | F2: 45192 | G2: =IF(F2="",1,0) -> 0 | H2: =IF(AND(G2=1,D2<Synthese!$B$3),1,0) -> 0 | I2: =IF(G2=1,E2,0) -> 0 | J2: =IF(H2=1,E2,0) -> 0
A3: FAC-0002 | B3: CH-2023-001 | C3: 45156 | D3: 45201 | E3: 26220 | G3: =IF(F3="",1,0) -> 1 | H3: =IF(AND(G3=1,D3<Synthese!$B$3),1,0) -> 1 | I3: =IF(G3=1,E3,0) -> 26220 | J3: =IF(H3=1,E3,0) -> 26220
A4: FAC-0003 | B4: CH-2023-002 | C4: 45238 | D4: 45283 | E4: 21795 | F4: 45285 | G4: =IF(F4="",1,0) -> 0 | H4: =IF(AND(G4=1,D4<Synthese!$B$3),1,0) -> 0 | I4: =IF(G4=1,E4,0) -> 0 | J4: =IF(H4=1,E4,0) -> 0
A5: FAC-0004 | B5: CH-2023-002 | C5: 45267 | D5: 45297 | E5: 43590 | F5: 45302 | G5: =IF(F5="",1,0) -> 0 | H5: =IF(AND(G5=1,D5<Synthese!$B$3),1,0) -> 0 | I5: =IF(G5=1,E5,0) -> 0 | J5: =IF(H5=1,E5,0) -> 0
A6: FAC-0005 | B6: CH-2023-002 | C6: 45307 | D6: 45337 | E6: 43590 | F6: 45338 | G6: =IF(F6="",1,0) -> 0 | H6: =IF(AND(G6=1,D6<Synthese!$B$3),1,0) -> 0 | I6: =IF(G6=1,E6,0) -> 0 | J6: =IF(H6=1,E6,0) -> 0
A7: FAC-0006 | B7: CH-2023-002 | C7: 45350 | D7: 45395 | E7: 36325 | F7: 45396 | G7: =IF(F7="",1,0) -> 0 | H7: =IF(AND(G7=1,D7<Synthese!$B$3),1,0) -> 0 | I7: =IF(G7=1,E7,0) -> 0 | J7: =IF(H7=1,E7,0) -> 0
A8: FAC-0007 | B8: CH-2023-003 | C8: 45268 | D8: 45313 | E8: 16275 | F8: 45314 | G8: =IF(F8="",1,0) -> 0 | H8: =IF(AND(G8=1,D8<Synthese!$B$3),1,0) -> 0 | I8: =IF(G8=1,E8,0) -> 0 | J8: =IF(H8=1,E8,0) -> 0
A9: FAC-0008 | B9: CH-2023-003 | C9: 45316 | D9: 45361 | E9: 22785 | F9: 45364 | G9: =IF(F9="",1,0) -> 0 | H9: =IF(AND(G9=1,D9<Synthese!$B$3),1,0) -> 0 | I9: =IF(G9=1,E9,0) -> 0 | J9: =IF(H9=1,E9,0) -> 0
A10: FAC-0009 | B10: CH-2023-003 | C10: 45355 | D10: 45400 | E10: 26040 | F10: 45403 | G10: =IF(F10="",1,0) -> 0 | H10: =IF(AND(G10=1,D10<Synthese!$B$3),1,0) -> 0 | I10: =IF(G10=1,E10,0) -> 0 | J10: =IF(H10=1,E10,0) -> 0
A11: FAC-0010 | B11: CH-2023-004 | C11: 45030 | D11: 45075 | E11: 28525 | F11: 45079 | G11: =IF(F11="",1,0) -> 0 | H11: =IF(AND(G11=1,D11<Synthese!$B$3),1,0) -> 0 | I11: =IF(G11=1,E11,0) -> 0 | J11: =IF(H11=1,E11,0) -> 0
A12: FAC-0011 | B12: CH-2023-004 | C12: 45087 | D12: 45117 | E12: 39935 | F12: 45119 | G12: =IF(F12="",1,0) -> 0 | H12: =IF(AND(G12=1,D12<Synthese!$B$3),1,0) -> 0 | I12: =IF(G12=1,E12,0) -> 0 | J12: =IF(H12=1,E12,0) -> 0
A13: FAC-0012 | B13: CH-2023-004 | C13: 45136 | D13: 45166 | E13: 45640 | F13: 45166 | G13: =IF(F13="",1,0) -> 0 | H13: =IF(AND(G13=1,D13<Synthese!$B$3),1,0) -> 0 | I13: =IF(G13=1,E13,0) -> 0 | J13: =IF(H13=1,E13,0) -> 0
A14: FAC-0013 | B14: CH-2023-005 | C14: 45079 | D14: 45124 | E14: 13800 | F14: 45124 | G14: =IF(F14="",1,0) -> 0 | H14: =IF(AND(G14=1,D14<Synthese!$B$3),1,0) -> 0 | I14: =IF(G14=1,E14,0) -> 0 | J14: =IF(H14=1,E14,0) -> 0
A15: FAC-0014 | B15: CH-2023-005 | C15: 45109 | D15: 45154 | E15: 20700 | F15: 45154 | G15: =IF(F15="",1,0) -> 0 | H15: =IF(AND(G15=1,D15<Synthese!$B$3),1,0) -> 0 | I15: =IF(G15=1,E15,0) -> 0 | J15: =IF(H15=1,E15,0) -> 0
... A41: FAC-0040 | B41: CH-2023-013 | C41: 45251 | D41: 45311 | E41: 33110 | F41: 45327 | G41: =IF(F41="",1,0) -> 0 | H41: =IF(AND(G41=1,D41<Synthese!$B$3),1,0) -> 0 | I41: =IF(G41=1,E41,0) -> 0 | J41: =IF(H41=1,E41,0) -> 0
A42: FAC-0041 | B42: CH-2023-013 | C42: 45321 | D42: 45381 | E42: 37840 | G42: =IF(F42="",1,0) -> 1 | H42: =IF(AND(G42=1,D42<Synthese!$B$3),1,0) -> 1 | I42: =IF(G42=1,E42,0) -> 37840 | J42: =IF(H42=1,E42,0) -> 37840
A43: FAC-0042 | B43: CH-2023-014 | C43: 45265 | D43: 45295 | E43: 14200 | F43: 45299 | G43: =IF(F43="",1,0) -> 0 | H43: =IF(AND(G43=1,D43<Synthese!$B$3),1,0) -> 0 | I43: =IF(G43=1,E43,0) -> 0 | J43: =IF(H43=1,E43,0) -> 0
A44: FAC-0043 | B44: CH-2023-014 | C44: 45303 | D44: 45333 | E44: 21300 | F44: 45335 | G44: =IF(F44="",1,0) -> 0 | H44: =IF(AND(G44=1,D44<Synthese!$B$3),1,0) -> 0 | I44: =IF(G44=1,E44,0) -> 0 | J44: =IF(H44=1,E44,0) -> 0
A45: FAC-0044 | B45: CH-2023-015 | C45: 45066 | D45: 45111 | E45: 28860 | F45: 45110 | G45: =IF(F45="",1,0) -> 0 | H45: =IF(AND(G45=1,D45<Synthese!$B$3),1,0) -> 0 | I45: =IF(G45=1,E45,0) -> 0 | J45: =IF(H45=1,E45,0) -> 0
A46: FAC-0045 | B46: CH-2023-015 | C46: 45098 | D46: 45143 | E46: 57720 | F46: 45140 | G46: =IF(F46="",1,0) -> 0 | H46: =IF(AND(G46=1,D46<Synthese!$B$3),1,0) -> 0 | I46: =IF(G46=1,E46,0) -> 0 | J46: =IF(H46=1,E46,0) -> 0
A47: FAC-0046 | B47: CH-2023-015 | C47: 45135 | D47: 45180 | E47: 57720 | F47: 45178 | G47: =IF(F47="",1,0) -> 0 | H47: =IF(AND(G47=1,D47<Synthese!$B$3),1,0) -> 0 | I47: =IF(G47=1,E47,0) -> 0 | J47: =IF(H47=1,E47,0) -> 0
A48: FAC-0047 | B48: CH-2023-015 | C48: 45150 | D48: 45180 | E48: 48100 | F48: 45177 | G48: =IF(F48="",1,0) -> 0 | H48: =IF(AND(G48=1,D48<Synthese!$B$3),1,0) -> 0 | I48: =IF(G48=1,E48,0) -> 0 | J48: =IF(H48=1,E48,0) -> 0
A49: FAC-0048 | B49: CH-2023-016 | C49: 45068 | D49: 45128 | E49: 23775 | F49: 45170 | G49: =IF(F49="",1,0) -> 0 | H49: =IF(AND(G49=1,D49<Synthese!$B$3),1,0) -> 0 | I49: =IF(G49=1,E49,0) -> 0 | J49: =IF(H49=1,E49,0) -> 0
A50: FAC-0049 | B50: CH-2023-016 | C50: 45111 | D50: 45156 | E50: 47550 | F50: 45160 | G50: =IF(F50="",1,0) -> 0 | H50: =IF(AND(G50=1,D50<Synthese!$B$3),1,0) -> 0 | I50: =IF(G50=1,E50,0) -> 0 | J50: =IF(H50=1,E50,0) -> 0
A51: FAC-0050 | B51: CH-2023-016 | C51: 45158 | D51: 45203 | E51: 47550 | F51: 45259 | G51: =IF(F51="",1,0) -> 0 | H51: =IF(AND(G51=1,D51<Synthese!$B$3),1,0) -> 0 | I51: =IF(G51=1,E51,0) -> 0 | J51: =IF(H51=1,E51,0) -> 0
A52: FAC-0051 | B52: CH-2023-016 | C52: 45201 | D52: 45261 | E52: 39625 | G52: =IF(F52="",1,0) -> 1 | H52: =IF(AND(G52=1,D52<Synthese!$B$3),1,0) -> 1 | I52: =IF(G52=1,E52,0) -> 39625 | J52: =IF(H52=1,E52,0) -> 39625
A53: FAC-0052 | B53: CH-2023-017 | C53: 45223 | D53: 45253 | E53: 17100 | F53: 45281 | G53: =IF(F53="",1,0) -> 0 | H53: =IF(AND(G53=1,D53<Synthese!$B$3),1,0) -> 0 | I53: =IF(G53=1,E53,0) -> 0 | J53: =IF(H53=1,E53,0) -> 0
A54: FAC-0053 | B54: CH-2023-017 | C54: 45251 | D54: 45281 | E54: 23940 | F54: 45278 | G54: =IF(F54="",1,0) -> 0 | H54: =IF(AND(G54=1,D54<Synthese!$B$3),1,0) -> 0 | I54: =IF(G54=1,E54,0) -> 0 | J54: =IF(H54=1,E54,0) -> 0
A55: FAC-0054 | B55: CH-2023-017 | C55: 45277 | D55: 45307 | E55: 27360 | G55: =IF(F55="",1,0) -> 1 | H55: =IF(AND(G55=1,D55<Synthese!$B$3),1,0) -> 1 | I55: =IF(G55=1,E55,0) -> 27360 | J55: =IF(H55=1,E55,0) -> 27360
A56: FAC-0055 | B56: CH-2023-018 | C56: 45051 | D56: 45096 | E56: 24360 | F56: 45100 | G56: =IF(F56="",1,0) -> 0 | H56: =IF(AND(G56=1,D56<Synthese!$B$3),1,0) -> 0 | I56: =IF(G56=1,E56,0) -> 0 | J56: =IF(H56=1,E56,0) -> 0
A57: FAC-0056 | B57: CH-2023-018 | C57: 45073 | D57: 45103 | E57: 48720 | F57: 45101 | G57: =IF(F57="",1,0) -> 0 | H57: =IF(AND(G57=1,D57<Synthese!$B$3),1,0) -> 0 | I57: =IF(G57=1,E57,0) -> 0 | J57: =IF(H57=1,E57,0) -> 0
A58: FAC-0057 | B58: CH-2023-018 | C58: 45106 | D58: 45136 | E58: 48720 | F58: 45136 | G58: =IF(F58="",1,0) -> 0 | H58: =IF(AND(G58=1,D58<Synthese!$B$3),1,0) -> 0 | I58: =IF(G58=1,E58,0) -> 0 | J58: =IF(H58=1,E58,0) -> 0
A59: FAC-0058 | B59: CH-2023-018 | C59: 45123 | D59: 45168 | E59: 40600 | F59: 45183 | G59: =IF(F59="",1,0) -> 0 | H59: =IF(AND(G59=1,D59<Synthese!$B$3),1,0) -> 0 | I59: =IF(G59=1,E59,0) -> 0 | J59: =IF(H59=1,E59,0) -> 0
A60: FAC-0059 | B60: CH-2024-001 | C60: 45571 | D60: 45601 | E60: 20720 | F60: 45599 | G60: =IF(F60="",1,0) -> 0 | H60: =IF(AND(G60=1,D60<Synthese!$B$3),1,0) -> 0 | I60: =IF(G60=1,E60,0) -> 0 | J60: =IF(H60=1,E60,0) -> 0
A61: FAC-0060 | B61: CH-2024-001 | C61: 45611 | D61: 45641 | E61: 31080 | F61: 45649 | G61: =IF(F61="",1,0) -> 0 | H61: =IF(AND(G61=1,D61<Synthese!$B$3),1,0) -> 0 | I61: =IF(G61=1,E61,0) -> 0 | J61: =IF(H61=1,E61,0) -> 0
A62: FAC-0061 | B62: CH-2024-002 | C62: 45366 | D62: 45411 | E62: 30975 | F62: 45411 | G62: =IF(F62="",1,0) -> 0 | H62: =IF(AND(G62=1,D62<Synthese!$B$3),1,0) -> 0 | I62: =IF(G62=1,E62,0) -> 0 | J62: =IF(H62=1,E62,0) -> 0
A63: FAC-0062 | B63: CH-2024-002 | C63: 45431 | D63: 45476 | E63: 43365 | F63: 45504 | G63: =IF(F63="",1,0) -> 0 | H63: =IF(AND(G63=1,D63<Synthese!$B$3),1,0) -> 0 | I63: =IF(G63=1,E63,0) -> 0 | J63: =IF(H63=1,E63,0) -> 0
A64: FAC-0063 | B64: CH-2024-002 | C64: 45508 | D64: 45553 | E64: 49560 | F64: 45554 | G64: =IF(F64="",1,0) -> 0 | H64: =IF(AND(G64=1,D64<Synthese!$B$3),1,0) -> 0 | I64: =IF(G64=1,E64,0) -> 0 | J64: =IF(H64=1,E64,0) -> 0
A65: FAC-0064 | B65: CH-2024-003 | C65: 45352 | D65: 45397 | E65: 17920 | F65: 45399 | G65: =IF(F65="",1,0) -> 0 | H65: =IF(AND(G65=1,D65<Synthese!$B$3),1,0) -> 0 | I65: =IF(G65=1,E65,0) -> 0 | J65: =IF(H65=1,E65,0) -> 0
...

Sheet Dictionnaire
A1: Table | B1: Colonne | C1: Description | D1: Usage principal
A2: Chantiers | B2: chantier_id | C2: Identifiant unique chantier | D2: Relation avec coûts et factures
A3: Chantiers | B3: nom_chantier | C3: Nom fictif du chantier | D3: Filtre de sélection
A4: Chantiers | B4: client | C4: Nom client fictif | D4: Tableau de relance
A5: Chantiers | B5: type_client | C5: Entreprise / Collectivité / Promoteur / Bailleur social / Particulier | D5: Analyse de délais de paiement
A6: Chantiers | B6: type_travaux | C6: Catégorie de travaux | D6: Analyse de marge
A7: Chantiers | B7: code_postal | C7: Code postal du chantier | D7: Filtre géographique
A8: Chantiers | B8: ville | C8: Ville chantier | D8: Confort de lecture
A9: Chantiers | B9: date_debut | C9: Date de démarrage | D9: Saisonnalité
A10: Chantiers | B10: date_fin_prevue | C10: Fin prévue | D10: Écart planning
A11: Chantiers | B11: date_fin_reelle | C11: Fin réelle | D11: Écart planning
A12: Chantiers | B12: ca_prevu_ht | C12: CA prévu au lancement | D12: Prévu vs réalisé
... A24: Factures | B24: date_paiement | C24: Date réelle de paiement (vide = impayé) | D24: Encaissement / trésorerie
